Workbook

Sheet Dados
A1: INFORMAÇÕES
F2: PREÇO CLIENTE DIBRACAM ESTOQUE 2 UNIDADES EM 26/12 | H2: 125000
F3: DEPOIS 16/17 | H3: 137000
F4: reduzir comissão dibracam para 2%
A5: DATAS (Premissas)
B6: Entrada Aquisição Equipamentos (Caminhões+Implementos) | C6: 42705 | H6: prazo
B7: Financiamento - Meses de Carência | C7: 0 | E7: Caminhão | F7: VW 8.160 Delivery 16/17 (4300mm entreeixos) | G7: 110250
B8: Início das parcelas | C8: =EDATE(C6,C7) -> 42705 | E8: Baú | F8: Alumínio/Teto Isolado/Carbus | G8: =19500 -> 19500 | H8: a combinar (Carbus) / 30 dias da confirmação / 10 unidades semana (Facchini)
B9: Meses para entrar em operação | C9: 2 | E9: Plataforma | F9: HBZ | G9: 13450 | H9: 1 a 2 dias úteis após entrega do baú
B10: Início das operações/contrato | C10: =EDATE(C6,C9) -> 42767 | G10: =SUM(G7:G9) -> 143200
B11: Meses para vender os caminhões após o fim do contrato | C11: 2
B12: Venda dos caminhões | C12: =EDATE(C15,C11) -> 43191 | F12: Manutenção Plataforma / Semestral | G12: 600
A13: Cenário I | B13: Duração do Contrato (em meses) - Cenário I | C13: 12 | F13: Sensor de Ré / Sensor Cinto | G13: 500
B14: Franquia mensal de KM | C14: 0 | F14: Adesivagem (SEM ORÇAMENTO) | G14: 2150
B15: Fim das operações/contrato | C15: =EDATE(C10,C13) -> 43132
B16: Venda dos caminhões | C16: =EDATE(C15,2) -> 43191
B17: Despesas Administrativas Gerais/mês/unidade
A18: Reajuste - Correção Monetária
B19: Periodicidade (em meses) | C19: 12 | E19: Escalonamento de Preços
B20: Mês em que incidirá o reajuste | C20: =EDATE(C10,C19) -> 43132
B21: Índice a ser adotado | C21: IGP-M | E21: Valor | F21: Ano
B22: Valor índice de reajustes previsto | C22: 0.03 | D22: atencção | E22: =C33 -> 297000 | F22: 0
A23: Desvalorização Mercado - Depreciação Real | D23: 0.22 | E23: =E22*(1-D23) -> 231660 | F23: 1
A24: Veículo | B24: % de depreciação (ao ano) | C24: preço de venda | D24: 0.12 | E24: =E23*(1-D24) -> 203860.8 | F24: 2
A25: Implemento | B25: % de depreciação (ao ano) | C25: preço de venda | D25: 0.12 | E25: =E24*(1-D25) -> 179397.5 | F25: 3
A26: Cenário I | B26: Depreciação em 12 meses - Veículo | D26: 0.12 | E26: =E25*(1-D26) -> 157869.8 | F26: 4
D27: 0.12 | E27: =E26*(1-D27) -> 138925.43 | F27: 5
A28: Valores de Compra | E28: =1*0.8*0.85 -> 0.68
A29: express | B29: Valor/un. | C29: 275000 | E29: Comissão Dibracam Venda usado | F29: 0.058 | H29: =C32 -> 297000
A30: carroceria | B30: Valor/un. | C30: 22000 | D30: =C30*0.3 -> 6600
A31: Adesivos e Acessórios | B31: Valor/un. (fornecedor Braspeso) | D31: Não Finamizável
A32: Equipamento (veículo + Implemento) | B32: Valor/un. | C32: =C29+C30 -> 297000
A33: Valor Total Equipamento + Peso | B33: Valor/un. | C33: =SUM(C31:C32) -> 297000
A34: Valores de Venda - Após encerramento do contrato
A35: Anos de uso no contrato | C35: 2 | D35: % do Valor de Compra | E35: % desvalorização ao término do contrato
A36: =A29 -> express | B36: Valor/un. | C36: 218223.72 | D36: =C36/(C29+C30) -> 0.73476 | E36: =1-D36 -> 0.26524
A37: Depreciação Contábil Ativo Imobilizado (Equipamento - Veículo + Implemento)
A38: Taxa de Depreciação a.a | C38: 0.25
A39: Taxa de Depreciação a.m | C39: =C38/12 -> 0.020833333
A40: Valor de Aquisição a ser depreciado | C40: =C32 -> 297000
...

Sheet Cashflow
G1: Premissas
G2: Contrato (em meses) | H2: 12
G3: Modelo | H3: =Dados!A29 -> express
G4: Franquia KM/mês | H4: =Dados!C14 -> 0
J5: ANO 1 | V5: OPERAÇÃO ENCERRADA
E6: 6
H7: 43466 | I7: =EDATE(H7,1) -> 43497 | J7: =EDATE(I7,1) -> 43525 | K7: =EDATE(J7,1) -> 43556 | L7: =EDATE(K7,1) -> 43586 | M7: =EDATE(L7,1) -> 43617 | N7: =EDATE(M7,1) -> 43647 | O7: =EDATE(N7,1) -> 43678 | P7: =EDATE(O7,1) -> 43709 | ... X7: =EDATE(W7,1) -> 43952
G8: mês corrido (a partir do deal) | H8: 0 | I8: =H8+1 -> 1 | J8: =I8+1 -> 2 | K8: =J8+1 -> 3 | L8: =K8+1 -> 4 | M8: =L8+1 -> 5 | N8: =M8+1 -> 6 | O8: =N8+1 -> 7 | P8: =O8+1 -> 8 | ... X8: =W8+1 -> 16
A9: preço de custo | G9: mês operação | J9: 1 | K9: =J9+1 -> 2 | L9: =K9+1 -> 3 | M9: =L9+1 -> 4 | N9: =M9+1 -> 5 | O9: =N9+1 -> 6 | P9: =O9+1 -> 7 | Q9: =P9+1 -> 8 | R9: =Q9+1 -> 9 | ... U9: =T9+1 -> 12 | V9: OPERAÇÃO ENCERRADA
A10: preço de venda | F10: 1 | G10: Investimento
F11: =F10+1 -> 2 | G11: Total | H11: ='Financ '!B88 -> 0 | I11: ='Financ '!C88 -> 26404.766 | J11: ='Financ '!D88 -> 26404.766 | K11: ='Financ '!E88 -> 26404.766 | L11: ='Financ '!F88 -> 26404.766 | M11: ='Financ '!G88 -> 26404.766 | N11: ='Financ '!H88 -> 26404.766 | O11: ='Financ '!I88 -> 26404.766 | ... T11: ='Financ '!N88 -> 26404.766
F12: =F11+1 -> 3
F13: =F12+1 -> 4 | G13: Despesas Operacionais (Representam Saída de Caixa) | H13: =SUM(H14:H18) -> 0 | I13: =SUM(I14:I18) -> 4921.35 | J13: =SUM(J14:J18) -> 0 | K13: =SUM(K14:K18) -> 0 | L13: =SUM(L14:L18) -> 0 | M13: =SUM(M14:M18) -> 0 | N13: =SUM(N14:N18) -> 0 | O13: =SUM(O14:O18) -> 0 | ... X13: =SUM(X14:X18) -> 0
F14: =F13+1 -> 5 | G14: IPVA | I14: =Licenciamento!E7 -> 4921.35 | T14: =Licenciamento!H7 -> 4471.35
F15: =F14+1 -> 6 | G15: Desp. Gerais administrativas | J15: =Dados!$C$17 -> 0 | K15: =Dados!$C$17 -> 0 | L15: =Dados!$C$17 -> 0 | M15: =Dados!$C$17 -> 0 | N15: =Dados!$C$17 -> 0 | O15: =Dados!$C$17 -> 0 | P15: =Dados!$C$17 -> 0 | Q15: =Dados!$C$17 -> 0 | ... X15: =Dados!$C$17 -> 0
F16: =F15+1 -> 7 | G16: Rastreamento | K16: ='Seguros-Rastreamento'!$E$4 -> 0 | L16: ='Seguros-Rastreamento'!$E$4 -> 0 | M16: ='Seguros-Rastreamento'!$E$4 -> 0 | N16: ='Seguros-Rastreamento'!$E$4 -> 0 | O16: ='Seguros-Rastreamento'!$E$4 -> 0 | P16: ='Seguros-Rastreamento'!$E$4 -> 0 | Q16: ='Seguros-Rastreamento'!$E$4 -> 0 | R16: ='Seguros-Rastreamento'!$E$4 -> 0 | ... U16: ='Seguros-Rastreamento'!$E$4 -> 0 | V16: ='Seguros-Rastreamento'!$E$5 -> 0
F17: =F16+1 -> 8 | G17: Seguro Contra 3os | J17: ='Seguros-Rastreamento'!$G$12 -> 0 | K17: ='Seguros-Rastreamento'!$G$12 -> 0 | L17: ='Seguros-Rastreamento'!$G$12 -> 0 | M17: ='Seguros-Rastreamento'!$G$12 -> 0 | N17: ='Seguros-Rastreamento'!$G$12 -> 0 | O17: ='Seguros-Rastreamento'!$G$12 -> 0
F18: =F17+1 -> 9 | G18: Manutenção | K18: =Manutenção!$D$36 -> 0 | L18: =Manutenção!$D$36 -> 0 | M18: =Manutenção!$D$36 -> 0 | N18: =Manutenção!$D$36 -> 0 | O18: =Manutenção!$D$36 -> 0 | P18: =Manutenção!$D$36 -> 0 | Q18: =Manutenção!$D$36 -> 0 | R18: =Manutenção!$D$36 -> 0 | ... U18: =Manutenção!$D$36 -> 0 | V18: =Manutenção!$J$36 -> 0
F19: =F18+1 -> 10
F20: =F19+1 -> 11 | G20: Despesas Operacionais que NÃO Representam Saída de Caixa
F21: =F20+1 -> 12 | G21: Depreciação Contábil Veículos | J21: =Dados!$C$41 -> 6187.5 | K21: =Dados!$C$41 -> 6187.5 | L21: =Dados!$C$41 -> 6187.5 | M21: =Dados!$C$41 -> 6187.5 | N21: =Dados!$C$41 -> 6187.5 | O21: =Dados!$C$41 -> 6187.5 | P21: =Dados!$C$41 -> 6187.5 | Q21: =Dados!$C$41 -> 6187.5 | ... X21: =Dados!$C$41 -> 6187.5
F22: =F21+1 -> 13
F23: =F22+1 -> 14
F24: =F23+1 -> 15 | G24: Índice Reajuste Anual
F25: =F24+1 -> 16 | G25: =Dados!C21 -> IGP-M
F26: =F25+1 -> 17
F27: =F26+1 -> 18 | G27: Receita Operacional Bruta | H27: Entrada/Fecham. DEAL | I27: 30 dias | J27: Início da operação | K27: Recebimento 1a Fatura (D+30) | V27: Venda dos Equipamentos + Receb. Última Fatura
F28: =F27+1 -> 19 | G28: Locação Equipamentos | H28: 0 | I28: 0 | J28: 0 | K28: =H66 -> 13995 | L28: =$K$28 -> 13995 | M28: =$K$28 -> 13995 | N28: =$K$28 -> 13995 | O28: =$K$28 -> 13995 | P28: =$K$28 -> 13995 | Q28: =$K$28 -> 13995 | R28: =$K$28 -> 13995 | S28: =$K$28 -> 13995 | ... U28: =$K$28 -> 13995 | V28: =$K$28*(1+Dados!$C$22) -> 14414.85
F29: =F28+1 -> 20
F30: =F29+1 -> 21 | G30: Receita Não Operacional | X30: Venda Equipamentos
F31: =F30+1 -> 22 | G31: Receita Não Operacional 1 - Venda Implementos | X31: 0
F32: =F31+1 -> 23 | G32: Receita Não Operacional 2 - Venda Veículos | X32: =H96 -> 213451.41
F33: =F32+1 -> 24
F34: =F33+1 -> 25 | G34: Impostos sobre Receita
F35: =F34+1 -> 26 | G35: Sobre Receita Operacional
F36: =F35+1 -> 27 | G36: PIS/COFINS | H36: =Tributos!$B$5*SUM(H28) -> 0 | I36: =Tributos!$B$5*SUM(I28) -> 0 | J36: =Tributos!$B$5*SUM(J28) -> 0 | K36: =Tributos!$B$5*SUM(K28) -> 510.8175 | L36: =Tributos!$B$5*SUM(L28) -> 510.8175 | M36: =Tributos!$B$5*SUM(M28) -> 510.8175 | N36: =Tributos!$B$5*SUM(N28) -> 510.8175 | O36: =Tributos!$B$5*SUM(O28) -> 510.8175 | ... X36: =Tributos!$B$5*SUM(X28) -> 0
F37: =F36+1 -> 28
F38: =F37+1 -> 29 | G38: Receita Líquida
F39: =F38+1 -> 30 | G39: Receita Operacional Líquida
F40: =F39+1 -> 31 | H40: =SUM(H28)-H36 -> 0 | I40: =SUM(I28)-I36 -> 0 | J40: =SUM(J28)-J36 -> 0 | K40: =SUM(K28)-K36 -> 13484.183 | L40: =SUM(L28)-L36 -> 13484.183 | M40: =SUM(M28)-M36 -> 13484.183 | N40: =SUM(N28)-N36 -> 13484.183 | O40: =SUM(O28)-O36 -> 13484.183 | ... X40: =SUM(X28)-X36 -> 0
...

Sheet Financ 
A1: Financiamento e Investimentos
A3: 19-420 | C3: Meses de Contrato de Serviço | D3: 12
C5: Meses para entrar em operação | D5: 3
C6: Meses de Financiamento | D6: =D3+D5 -> 15
A8: UNITÁRIO
A9: Valor Financiamento | B9: 260000
B11: =Dados!C6 -> 42705 | C11: =EDATE(B11,1) -> 42736 | D11: =EDATE(C11,1) -> 42767 | E11: =EDATE(D11,1) -> 42795 | F11: =EDATE(E11,1) -> 42826 | G11: =EDATE(F11,1) -> 42856 | H11: =EDATE(G11,1) -> 42887 | I11: =EDATE(H11,1) -> 42917 | J11: =EDATE(I11,1) -> 42948 | ... O11: =EDATE(N11,1) -> 43101 | X11: =EDATE(O11,1) -> 43132 | Y11: =EDATE(X11,1) -> 43160
B12: 0 | C12: 1 | D12: 2 | E12: 3 | F12: 4 | G12: 5 | H12: 6 | I12: 7 | J12: 8 | K12: 9 | L12: 10 | M12: 11 | N12: 12 | O12: 13 | X12: 14 | Y12: 15
A13: Entrada/Parcelas/Quitação | B13: 0 | C13: 0 | D13: 0 | E13: 4226.04 | F13: 0 | G13: 0 | H13: 3678.48 | I13: 6387.9 | J13: 6321.82 | K13: 6417.5 | L13: 6233.47 | M13: 6248.4 | N13: 6299.2 | O13: 6172.51 | X13: 6210.86 | Y13: 219215.68
A15: LOTE
A16: Qtdade (unidades) | B16: 1
A17: Valor Total Financiado | B17: =B16*B9 -> 260000
B19: =Dados!C6 -> 42705 | C19: =EDATE(B19,1) -> 42736 | D19: =EDATE(C19,1) -> 42767 | E19: =EDATE(D19,1) -> 42795 | F19: =EDATE(E19,1) -> 42826 | G19: =EDATE(F19,1) -> 42856 | H19: =EDATE(G19,1) -> 42887 | I19: =EDATE(H19,1) -> 42917 | J19: =EDATE(I19,1) -> 42948 | ... O19: =EDATE(N19,1) -> 43101 | X19: =EDATE(O19,1) -> 43132 | Y19: =EDATE(X19,1) -> 43160
B20: 0 | C20: =B20+1 -> 1 | D20: =C20+1 -> 2 | E20: =D20+1 -> 3 | F20: =E20+1 -> 4 | G20: =F20+1 -> 5 | H20: =G20+1 -> 6 | I20: =H20+1 -> 7 | J20: =I20+1 -> 8 | ... O20: =N20+1 -> 13 | X20: =O20+1 -> 14 | Y20: =X20+1 -> 15
A21: Entrada/Parcelas/Quitação | B21: =B13*#REF! -> #REF! | C21: =C13*#REF! -> #REF! | D21: =D13*#REF! -> #REF! | E21: =E13*#REF! -> #REF! | F21: =F13*#REF! -> #REF! | G21: =G13*#REF! -> #REF! | H21: =H13*#REF! -> #REF! | I21: =I13*#REF! -> #REF! | ... O21: =O13*#REF! -> #REF! | X21: =X13*#REF! -> #REF! | Y21: =Y13*#REF! -> #REF!
A22: FINAME | B22: Proporção | C22: Taxa a.m | D22: Taxa a.a | E22: Prazo (em meses) | F22: Carência (em dias)
A23: TJLP | B23: 1 | C23: 0.0099 | D23: 0.135 | E23: 60 | F23: 180
A24: SELIC | B24: 0 | C24: 0.0141 | D24: 0.0648 | E24: 60 | F24: 180
B25: total | C25: 0.0124 | D25: =SUM(D23:D24) -> 0.1998 | E25: 60 | F25: 180
A26: CDC PJ | B26: 0 | C26: 0 | D26: 0 | E26: 0 | F26: 0
A27: Entrada | B27: 0 | C27: - | D27: - | E27: - | F27: -
A28: Preço Veículo | B28: =Dados!C29 -> 275000
A29: Preço Implemento | B29: =Dados!C30 -> 22000
A30: =Dados!A29 -> express | C30: Meses de Contrato de Serviço | D30: =Dados!C13 -> 12
C32: Meses para entrar em operação | D32: =Dados!C9 -> 2
C33: =Dados!B11 -> Meses para vender os caminhões após o fim do contrato | D33: =Dados!C11 -> 2
C34: Meses de Financiamento | D34: =Dados!C13+Dados!C9+Dados!C11 -> 16
A36: CDC | D36: =B37/4 -> 74250
A37: Valor Financiamento | B37: =((B28+B29)*B23)-B58-B78 -> 297000
A38: Taxa de juros | B38: 0.0101
B39: =Cashflow!H7 -> 43466 | C39: =EDATE(B39,1) -> 43497 | D39: =EDATE(C39,1) -> 43525 | E39: =EDATE(D39,1) -> 43556 | F39: =EDATE(E39,1) -> 43586 | G39: =EDATE(F39,1) -> 43617 | H39: =EDATE(G39,1) -> 43647 | I39: =EDATE(H39,1) -> 43678 | J39: =EDATE(I39,1) -> 43709 | ... BK39: =EDATE(BJ39,1) -> 45323
B40: =Cashflow!H8 -> 0 | C40: =B40+1 -> 1 | D40: =C40+1 -> 2 | E40: =D40+1 -> 3 | F40: =E40+1 -> 4 | G40: =F40+1 -> 5 | H40: =G40+1 -> 6 | I40: =H40+1 -> 7 | J40: =I40+1 -> 8 | ... BK40: =BJ40+1 -> 61
A41: Entrada/Parcelas/Quitação | C41: =-PMT($B$38,12,$B$37,,) -> 26404.766 | D41: =-PMT($B$38,12,$B$37,,) -> 26404.766 | E41: =-PMT($B$38,12,$B$37,,) -> 26404.766 | F41: =-PMT($B$38,12,$B$37,,) -> 26404.766 | G41: =-PMT($B$38,12,$B$37,,) -> 26404.766 | H41: =-PMT($B$38,12,$B$37,,) -> 26404.766 | I41: =-PMT($B$38,12,$B$37,,) -> 26404.766 | J41: =-PMT($B$38,12,$B$37,,) -> 26404.766 | ... N41: =-PMT($B$38,12,$B$37,,) -> 26404.766
A43: FINAME
A44: Valor Financiamento | B44: =(B28+B29)*B24 -> 0
B46: =Cashflow!H7 -> 43466 | C46: =EDATE(B46,1) -> 43497 | D46: =EDATE(C46,1) -> 43525 | E46: =EDATE(D46,1) -> 43556 | F46: =EDATE(E46,1) -> 43586 | G46: =EDATE(F46,1) -> 43617 | H46: =EDATE(G46,1) -> 43647 | I46: =EDATE(H46,1) -> 43678 | J46: =EDATE(I46,1) -> 43709 | ... BM46: =EDATE(BL46,1) -> 45383
B47: =Cashflow!H8 -> 0 | C47: =B47+1 -> 1 | D47: =C47+1 -> 2 | E47: =D47+1 -> 3 | F47: =E47+1 -> 4 | G47: =F47+1 -> 5 | H47: =G47+1 -> 6 | I47: =H47+1 -> 7 | J47: =I47+1 -> 8 | ... BM47: =BL47+1 -> 63
A48: Entrada/Parcelas/Quitação
A50: CDC PJ | C50: Data de início | D50: Prazo (meses) | E50: Qtde pgtos | F50: Parc. A serem pagas | G50: Parc. Restantes (trazer a Valor Present.) | H50: Valor Parcela | I50: Valor total restante - Valor de face | J50: Taxa de Juros a.m | K50: Taxa de Juros a.a | L50: Valor total restante - trazidos à Valor Presente
A51: Valor Financiamento | B51: =B28*B26 -> 0 | C51: =Dados!C6 -> 42705 | D51: 0 | E51: 0 | F51: 0 | G51: =E51-F51 -> 0 | H51: 0 | I51: =H51*G51 -> 0 | J51: 0 | K51: 0 | L51: =NPV(J51,AR55:BL55) -> 0
...

Sheet Receita
B1: Receita
A3: PREENCHER PRIMEIRO | B3: Preço ALVO FINAL | H3: INSTRUÇÕES
B4: Modelo + Implemento | C4: Un. | D4: Valor/Un. | E4: Valor Total | H4: 1 - Estabelecer Preço ALVO FINAL
B5: 19-420 18 meses 4k km | C5: 1 | D5: 9600 | E5: =C5*D5 -> 9600 | H5: 2 - Determinar Fator X
B6: 19-420 18 meses 6k km | C6: 1 | D6: 10000 | E6: =C6*D6 -> 10000 | H6: 3 - Enviar ao cliente Preço Inicial PRÉ-NEGOCIAÇÃO
B7: 19-420 18 meses 8k km | C7: 1 | D7: 10250 | E7: =C7*D7 -> 10250 | H7: 4 - Negociar com o cliente e inserir os preços FECHAMENTO DEAL
B8: 25-420 24 meses | E8: =C8*D8 -> 0
E9: =C9*D9 -> 0
E10: =C10*D10 -> 0
B11: Total caminhão | C11: =SUM(C5:C10) -> 3 | D11: =SUM(D5:D10) -> 29850 | E11: =SUM(E5:E10) -> 29850
B13: Preço Inicial PRÉ-NEGOCIAÇÃO
A14: ENVIAR AO CLIENTE | B14: Modelo + Implemento | C14: Un. | D14: Fator X | E14: Valor/Un. | F14: Valor Total
B15: 19-420 18 meses 4k km | C15: =C5 -> 1 | D15: 0.035 | E15: =D5*(1+D15) -> 9936 | F15: =C15*E15 -> 9936
B16: 17-190 + Roll-On + Garra | C16: =C6 -> 1 | D16: 0.0225 | E16: =D6*(1+D16) -> 10225 | F16: =C16*E16 -> 10225
C17: =C7 -> 1 | D17: 0.0487 | E17: =D7*(1+D17) -> 10749.175 | F17: =C17*E17 -> 10749.175
C18: =C8 -> 0 | D18: 0.0523 | E18: =D8*(1+D18) -> 0 | F18: =C18*E18 -> 0
C19: =C9 -> 0 | D19: 0.0222 | E19: =D9*(1+D19) -> 0 | F19: =C19*E19 -> 0
C20: =C10 -> 0 | D20: 0.032 | E20: =D10*(1+D20) -> 0 | F20: =C20*E20 -> 0
B21: Total caminhão | C21: =SUM(C15:C20) -> 3 | E21: =SUM(E15:E20) -> 30910.175 | F21: =SUM(F15:F20) -> 30910.175
B23: Preço Inicial PRÉ-NEGOCIAÇÃO/Preço ALVO FINAL | D23: =(F21/E11)-1 -> 0.03551675
A25: PREÇO FECHADO (DEAL) | B25: Preço FECHAMENTO DEAL
B26: Modelo + Implemento | C26: Un. | D26: Valor/Un. | E26: Valor Total
B27: 10-160 + Compactador | C27: =C5 -> 1 | D27: 9200 | E27: =C27*D27 -> 9200
B28: 17-190 + Roll-On + Garra | C28: =C6 -> 1 | D28: 12500 | E28: =C28*D28 -> 12500
C29: =C7 -> 1 | E29: =C29*D29 -> 0
C30: =C8 -> 0 | E30: =C30*D30 -> 0
C31: =C9 -> 0 | E31: =C31*D31 -> 0
C32: =C10 -> 0 | E32: =C32*D32 -> 0
B33: Total caminhão | C33: =SUM(C27:C32) -> 3 | D33: =SUM(D27:D32) -> 21700 | E33: =SUM(E27:E32) -> 21700
B35: Preço FECHAMENTO DEAL/Preço ALVO FINAL | D35: =(E33/E11)-1 -> -0.27303183

Sheet Tributos
A1: Tributos sobre Receita
B2: TOPE | C2: Dibracam
A3: PIS | B3: 0.0065 | C3: 0.0165
A4: COFINS | B4: 0.03 | C4: 0.076
A5: Total | B5: =SUM(B3:B4) -> 0.0365 | C5: =SUM(C3:C4) -> 0.0925
A7: Outros Impostos - TOPE - Regime Lucro Presumido
A8: IR (incide sobre 32% da receita) | B8: 0.15
A9: CSLL (incide sobre 32% da receita) | B9: 0.09
A10: Adicional IR (diretamente sobre a receita) | B10: 0.012

Sheet Seguros-Rastreamento
A1: RASTREAMENTO
A3: Rastreadora | B3: Valor/Un./Mês | C3: Ano | D3: Unidades | E3: Valor Total/Mês
A4: SASCAR | C4: 1 | D4: 1 | E4: =B4*D4 -> 0
C5: 2 | D5: 1 | E5: =E4*(1+$I$6) -> 0 | I5: Reajuste Anutal Estimado
C6: 3 | D6: 1 | E6: =E5*(1+$I$6) -> 0 | I6: 0.095
A9: SEGUROS CONTRA 3os - RCF
A11: Seguradora | B11: Modelo | C11: Ano | D11: Quantidade | E11: Preço Un/ano | F11: Parcelas | G11: Valor parcela
A12: TOKIO MARINE | B12: =Dados!A29 -> express | C12: 1 | D12: 1 | F12: 6 | G12: =E12/F12 -> 0
C13: 2 | D13: 1 | E13: =E12*($I$6+1) -> 0 | F13: 6 | G13: =E13/F13 -> 0
C14: 3 | D14: 1 | E14: =E13*($I$6+1) -> 0 | F14: 6 | G14: =E14/F14 -> 0

Sheet Manutenção
A1: Manutenção - Contrato de Manutenção VW/MAN
A3: Franquia KM/mês | B3: 4000
C4: Valor KM | D4: Valor mensal/unidade
A5: Modelo | B5: Unidades | C5: VALOR LINEAR 3 ANOS OU 360.000
A6: 19-420 | B6: 1 | C6: 0.1362 | D6: =C6*$B$3 -> 544.8
A7: 25-420 | B7: 1 | C7: 0.1362 | D7: =C7*$B$3 -> 544.8
A8: Total | B8: =SUM(B6:B7) -> 2
A11: Premissas:
A12: Pneus NÃO INCLUSOS NO CONTRATO DE MANUTENÇÃO, DEVENDO FICAR A CARGO DO LOCATÁRIO
A15: Franquia KM/mês | B15: 6000
C16: Valor KM | D16: Valor mensal/unidade
A17: Modelo | B17: Unidades | C17: VALOR LINEAR 3 ANOS OU 360.000
A18: 19-420 | B18: 1 | C18: 0.1362 | D18: =C18*$B$15 -> 817.2
A19: 25-420 | B19: 1 | C19: 0.1362 | D19: =C19*$B$15 -> 817.2
A20: Total | B20: =SUM(B18:B19) -> 2
A24: Franquia KM/mês | B24: 8000
C25: Valor KM | D25: Valor mensal/unidade
A26: Modelo | B26: Unidades | C26: VALOR LINEAR 3 ANOS OU 360.000
A27: 19-420 | B27: 1 | C27: 0.1362 | D27: =C27*$B$24 -> 1089.6
A28: 25-420 | B28: 1 | C28: 0.1362 | D28: =C28*$B$24 -> 1089.6
A29: Total | B29: =SUM(B27:B28) -> 2
A32: Franquia KM/mês | B32: =Dados!C14 -> 0 | C32: 1o Ano Veículo | E32: 2o Ano Veículo | G32: 3o Ano Veículo | I32: 4o Ano Veículo
A34: Modelo | C34: Valor KM | D34: Valor mensal/un. | E34: Valor KM | F34: Valor mensal/un. | G34: Valor KM | H34: Valor mensal/un. | I34: Valor KM | J34: Valor mensal/un.
A36: =Dados!A29 -> express | C36: 0 | D36: =C36*B32 -> 0 | E36: 0 | F36: =E36*B32 -> 0 | G36: 0 | H36: =G36*B32 -> 0 | I36: 0 | J36: =I36*B32 -> 0

Sheet Licenciamento
A1: LICENCIAMENTO
A2: Considerando 3% Desc. Pgto à Vista (janeiro)
A3: Valor Documentação = R$ 800
A4: Cenário - Preço Venda
C5: desp. 2019 | F5: Desp. 2019 (incide em Janeiro) | I5: Desp. 2019 (incide em Janeiro) | L5: Desp. 2020 (incide em Janeiro) | O5: Desp. 2021 (incide em Janeiro) | R5: Desp. 2022 (incide em Janeiro) | U5: Desp. 2023 (incide em Janeiro)
A6: Modelo | B6: Preço/Un | C6: IPVA | D6: Doc. | E6: Total/un | F6: IPVA | G6: Doc. | H6: Total/un | I6: IPVA | J6: Doc. | K6: Total/un. | L6: IPVA | M6: Doc. | N6: Total/un. | O6: IPVA | P6: Doc. | Q6: Total/un. | R6: IPVA | S6: Doc. | T6: Total/un. | U6: IPVA | V6: Doc. | W6: Total/un.
A7: =Dados!A29 -> express | B7: =Dados!C32 -> 297000 | C7: =((B7*0.015)*0.97) -> 4321.35 | D7: 600 | E7: =C7+D7 -> 4921.35 | F7: =(B7*0.015)*0.97 -> 4321.35 | G7: 150 | H7: =F7+G7 -> 4471.35 | I7: =((B7*0.85)*0.015)*0.97 -> 3673.1475 | J7: 150 | K7: =I7+J7 -> 3823.1475 | L7: =(((B7*0.85)*0.85)*0.015)*0.97 -> 3122.1754 | M7: 150 | N7: =L7+M7 -> 3272.1754 | O7: =((((B7*0.85)*0.85)*0.85)*0.015)*0.97 -> 2653.8491 | P7: 150 | Q7: =O7+P7 -> 2803.8491 | R7: =(((((B7*0.85)*0.85)*0.85)*0.85)*0.015)*0.97 -> 2255.7717 | S7: 150 | T7: =R7+S7 -> 2405.7717 | U7: =((((((B7*0.85)*0.85)*0.85)*0.85)*0.85)*0.015)*0.97 -> 1917.406 | V7: 150 | W7: =U7+V7 -> 2067.406

Sheet Sheet1
E8: 0.02254
D9: COEFICIENTE | E9: =E8*(1-4.3%) -> 0.02157078
E10: 179700 | G10: Parâmetros
E11: =E9*E10 -> 3876.2692 | I11: Custo Financeiro
G12: Mês | H12: 30 | I12: 0.008
G13: Dia | H13: 1 | I13: =I12/30 -> 0.00026666667
G15: Padrão | H15: 10 | I15: 0
G16: Prazo Cliente | H16: 90
H17: 30 | I17: =I13*20 -> 0.0053333333
H18: 60 | I18: =(I17)+I12 -> 0.013333333
H19: 90 | I19: =I18+0.8% -> 0.021333333
G20: Dias de Custo Financeiro | H20: =H16-H15 -> 80
C25: Valo | D25: res em | E25: 1 | F25: 79700
C26: Par | D26: cData V | E26: eSdo. Inic | F26: iaAmortização | G26: Juros | H26: PrestCorreção | I26: Prev. | J26: Sdo. FinT | K26: otal a pagar
C27: 0 | D27: 20/03/ | E27: 179700 | F27: 0 | G27: 0 | H27: 0 | I27: 0 | J27: 179700 | K27: 0
C28: 0 | D28: 15/04/ | E28: 179700 | F28: 0 | G28: 0 | H28: 0 | I28: 0 | J28: 179700 | K28: 0
C29: 0 | D29: 15/05/ | E29: 179700 | F29: 0 | G29: 0 | H29: 0 | I29: 0 | J29: 179700 | K29: 0
C30: 1 | D30: 15/06/ | E30: 179700 | F30: 0 | G30: 4802.3 | H30: 4802 | I30: 0 | J30: 179700 | K30: 179700
C31: 3 | D31: 15/10/ | E31: 179700 | F31: 3327.7 | G31: 1561.7 | H31: 4889 | I31: 0 | J31: 176372.22 | K31: 176372.22
C32: 4 | D32: 16/11/ | E32: 176372 | F32: 3327.7 | G32: 1686.8 | H32: 5014 | I32: 0 | J32: 173044.44 | K32: 173044.44
C33: 5 | D33: 17/12/ | E33: 173044 | F33: 3327.7 | G33: 1604.4 | H33: 4932 | I33: 0 | J33: 169716.66 | K33: 169716.66
C34: 6 | D34: 15/01/ | E34: 169716 | F34: 3327.7 | G34: 1475 | H34: 4802 | I34: 0 | J34: 166388.88 | K34: 166388.88
C35: 7 | D35: 15/02/ | E35: 166388 | F35: 3327.7 | G35: 1639.6 | H35: 4967 | I35: 0 | J35: 163061.1 | K35: 163061.1
C36: 8 | D36: 15/03/ | E36: 163061 | F36: 3327.7 | G36: 1370 | H36: 4697 | I36: 0 | J36: 159733.32 | K36: 159733.32
C37: 10 | D37: 15/05/ | E37: 156405 | F37: 3327.7 | G37: 1404.9 | H37: 4732 | I37: 0 | J37: 153077.76 | K37: 153077.76
C38: 11 | D38: 17/06/ | E38: 153077 | F38: 3327.7 | G38: 1508.4 | H38: 4836 | I38: 0 | J38: 149749.98 | K38: 149749.98
... C76: 55 | D76: 15/02/ | E76: 6655 | F76: 3327.7 | G76: 63.6 | H76: 3391 | I76: 0 | J76: 3327.66 | K76: 3327.66
C77: TOT | D77: AIS==>/ | E77: 3327 | F77: 179700 | G77: 55589.5 | H77: 235289 | I77: 0 | J77: 0 | K77: 0
C83: 0 | D83: 20/03/ | E83: 179700 | F83: 0 | G83: 0 | H83: 0 | I83: 0 | J83: 179700 | K83: 0
C84: 0 | D84: 15/04/ | E84: 179700 | F84: 0 | G84: 0 | H84: 0 | I84: 0 | J84: 179700 | K84: 0
C85: 0 | D85: 15/05/ | E85: 179700 | F85: 0 | G85: 0 | H85: 0 | I85: 0 | J85: 179700 | K85: 0
C86: 1 | D86: 15/06/ | E86: 179700 | F86: 0 | G86: 4802.3 | H86: 4802 | I86: 0 | J86: 179700 | K86: 179700
C87: 3 | D87: 15/10/ | E87: 179700 | F87: 3327.7 | G87: 1561.7 | H87: 4889 | I87: 0 | J87: 176372.22 | K87: 176372.22
C88: 4 | D88: 16/11/ | E88: 176372 | F88: 3327.7 | G88: 1686.8 | H88: 5014 | I88: 0 | J88: 173044.44 | K88: 173044.44
C89: 5 | D89: 17/12/ | E89: 173044 | F89: 3327.7 | G89: 1604.4 | H89: 4932 | I89: 0 | J89: 169716.66 | K89: 169716.66
C90: 6 | D90: 15/01/ | E90: 169716 | F90: 3327.7 | G90: 1475 | H90: 4802 | I90: 0 | J90: 166388.88 | K90: 166388.88
C91: 7 | D91: 15/02/ | E91: 166388 | F91: 3327.7 | G91: 1639.6 | H91: 4967 | I91: 0 | J91: 163061.1 | K91: 163061.1
C92: 8 | D92: 15/03/ | E92: 163061 | F92: 3327.7 | G92: 1370 | H92: 4697 | I92: 0 | J92: 159733.32 | K92: 159733.32
C93: 10 | D93: 15/05/ | E93: 156405 | F93: 3327.7 | G93: 1404.9 | H93: 4732 | I93: 0 | J93: 153077.76 | K93: 153077.76
C94: 11 | D94: 17/06/ | E94: 153077 | F94: 3327.7 | G94: 1508.4 | H94: 4836 | I94: 0 | J94: 149749.98 | K94: 149749.98
...
